Workbook

Sheet 2016年
A1: 天峨县林朵林场新场部危改房AB栋2016年度电梯维护费收缴情况登记表
A2: 编制部门：天峨县林朵林场计划财务科 | O2: 单位：元
A3: 编号 | B3: 房号 | C3: 原户主 | D3: 上年余额（+）或欠交（-） | E3: 1月已交 | F3: 2月已交 | G3: 3月已交 | H3: 4月已交 | I3: 5月已交 | J3: 6月已交 | K3: 7月已交 | L3: 8月已交 | M3: 9月已交 | N3: 10月已交 | O3: 11月已交 | P3: 12月已交 | Q3: 本年余额（+）或欠交（-）
A4: 1 | B4: A1801 | C4: 韦贞鸾 | Q4: =D4+E4+F4+G4+H4+I4+J4+K4+L4+M4+N4+O4+P4 -> 0
A5: 2 | B5: A1802 | C5: 杨桂玉 | Q5: =D5+E5+F5+G5+H5+I5+J5+K5+L5+M5+N5+O5+P5 -> 0
A6: 3 | B6: A1803 | C6: 胡远必 | Q6: =D6+E6+F6+G6+H6+I6+J6+K6+L6+M6+N6+O6+P6 -> 0
A7: 4 | B7: A1804 | C7: 梁小凤 | Q7: =D7+E7+F7+G7+H7+I7+J7+K7+L7+M7+N7+O7+P7 -> 0
A8: 5 | B8: A1701 | C8: 陈巧玲 | Q8: =D8+E8+F8+G8+H8+I8+J8+K8+L8+M8+N8+O8+P8 -> 0
A9: 6 | B9: A1702 | C9: 周凤琼 | Q9: =D9+E9+F9+G9+H9+I9+J9+K9+L9+M9+N9+O9+P9 -> 0
A10: 7 | B10: A1703 | C10: 班华钊 | Q10: =D10+E10+F10+G10+H10+I10+J10+K10+L10+M10+N10+O10+P10 -> 0
A11: 8 | B11: A1704 | C11: 孙慧芳 | Q11: =D11+E11+F11+G11+H11+I11+J11+K11+L11+M11+N11+O11+P11 -> 0
A12: 9 | B12: A1601 | C12: 赵花萄 | Q12: =D12+E12+F12+G12+H12+I12+J12+K12+L12+M12+N12+O12+P12 -> 0
A13: 10 | B13: A1602 | C13: 韦玉林 | Q13: =D13+E13+F13+G13+H13+I13+J13+K13+L13+M13+N13+O13+P13 -> 0
A14: 11 | B14: A1603 | C14: 李祖勋 | Q14: =D14+E14+F14+G14+H14+I14+J14+K14+L14+M14+N14+O14+P14 -> 0
A15: 12 | B15: A1604 | C15: 马尚军 | Q15: =D15+E15+F15+G15+H15+I15+J15+K15+L15+M15+N15+O15+P15 -> 0
... A127: 124 | B127: B404 | C127: 周冬梅 | Q127: =D127+E127+F127+G127+H127+I127+J127+K127+L127+M127+N127+O127+P127 -> 0
A128: 125 | B128: B301 | Q128: =D128+E128+F128+G128+H128+I128+J128+K128+L128+M128+N128+O128+P128 -> 0
A129: 126 | B129: B302 | C129: 田明川 | Q129: =D129+E129+F129+G129+H129+I129+J129+K129+L129+M129+N129+O129+P129 -> 0
A130: 127 | B130: B303 | C130: 韦仕斌 | Q130: =D130+E130+F130+G130+H130+I130+J130+K130+L130+M130+N130+O130+P130 -> 0
A131: 128 | B131: B304 | C131: 韦光伟 | Q131: =D131+E131+F131+G131+H131+I131+J131+K131+L131+M131+N131+O131+P131 -> 0
A132: 129 | C132: 合计 | D132: =SUM(D4:D131) -> 0 | E132: =SUM(E4:E131) -> 0 | F132: =SUM(F4:F131) -> 0 | G132: =SUM(G4:G131) -> 0 | H132: =SUM(H4:H131) -> 0 | I132: =SUM(I4:I131) -> 0 | J132: =SUM(J4:J131) -> 0 | K132: =SUM(K4:K131) -> 0 | ... Q132: =SUM(Q4:Q131) -> 0

Sheet 2017年 
A1: 天峨县林朵林场新场部危改房AB栋2017年度电梯维护费收缴情况登记表
A2: 编制部门：天峨县林朵林场计划财务科 | O2: 单位：元
A3: 编号 | B3: 房号 | C3: 原户主 | D3: 上年余额（+）或欠交（-） | E3: 1月已交 | F3: 2月已交 | G3: 3月已交 | H3: 4月已交 | I3: 5月已交 | J3: 6月已交 | K3: 7月已交 | L3: 8月已交 | M3: 9月已交 | N3: 10月已交 | O3: 11月已交 | P3: 12月已交 | Q3: 本年余额（+）或欠交（-）
A4: 1 | B4: A1801 | C4: 韦贞鸾 | Q4: =D4+E4+F4+G4+H4+I4+J4+K4+L4+M4+N4+O4+P4 -> 0
A5: 2 | B5: A1802 | C5: 杨桂玉 | Q5: =D5+E5+F5+G5+H5+I5+J5+K5+L5+M5+N5+O5+P5 -> 0
A6: 3 | B6: A1803 | C6: 胡远必 | Q6: =D6+E6+F6+G6+H6+I6+J6+K6+L6+M6+N6+O6+P6 -> 0
A7: 4 | B7: A1804 | C7: 梁小凤 | Q7: =D7+E7+F7+G7+H7+I7+J7+K7+L7+M7+N7+O7+P7 -> 0
A8: 5 | B8: A1701 | C8: 陈巧玲 | Q8: =D8+E8+F8+G8+H8+I8+J8+K8+L8+M8+N8+O8+P8 -> 0
A9: 6 | B9: A1702 | C9: 周凤琼 | Q9: =D9+E9+F9+G9+H9+I9+J9+K9+L9+M9+N9+O9+P9 -> 0
A10: 7 | B10: A1703 | C10: 班华钊 | Q10: =D10+E10+F10+G10+H10+I10+J10+K10+L10+M10+N10+O10+P10 -> 0
A11: 8 | B11: A1704 | C11: 孙慧芳 | Q11: =D11+E11+F11+G11+H11+I11+J11+K11+L11+M11+N11+O11+P11 -> 0
A12: 9 | B12: A1601 | C12: 赵花萄 | Q12: =D12+E12+F12+G12+H12+I12+J12+K12+L12+M12+N12+O12+P12 -> 0
A13: 10 | B13: A1602 | C13: 韦玉林 | Q13: =D13+E13+F13+G13+H13+I13+J13+K13+L13+M13+N13+O13+P13 -> 0
A14: 11 | B14: A1603 | C14: 李祖勋 | Q14: =D14+E14+F14+G14+H14+I14+J14+K14+L14+M14+N14+O14+P14 -> 0
A15: 12 | B15: A1604 | C15: 马尚军 | Q15: =D15+E15+F15+G15+H15+I15+J15+K15+L15+M15+N15+O15+P15 -> 0
... A127: 124 | B127: B404 | C127: 周冬梅 | Q127: =D127+E127+F127+G127+H127+I127+J127+K127+L127+M127+N127+O127+P127 -> 0
A128: 125 | B128: B301 | Q128: =D128+E128+F128+G128+H128+I128+J128+K128+L128+M128+N128+O128+P128 -> 0
A129: 126 | B129: B302 | C129: 田明川 | Q129: =D129+E129+F129+G129+H129+I129+J129+K129+L129+M129+N129+O129+P129 -> 0
A130: 127 | B130: B303 | C130: 韦仕斌 | Q130: =D130+E130+F130+G130+H130+I130+J130+K130+L130+M130+N130+O130+P130 -> 0
A131: 128 | B131: B304 | C131: 韦光伟 | Q131: =D131+E131+F131+G131+H131+I131+J131+K131+L131+M131+N131+O131+P131 -> 0
A132: 129 | C132: 合计 | D132: =SUM(D4:D131) -> 0 | E132: =SUM(E4:E131) -> 0 | F132: =SUM(F4:F131) -> 0 | G132: =SUM(G4:G131) -> 0 | H132: =SUM(H4:H131) -> 0 | I132: =SUM(I4:I131) -> 0 | J132: =SUM(J4:J131) -> 0 | K132: =SUM(K4:K131) -> 0 | ... Q132: =SUM(Q4:Q131) -> 0

Sheet 2018年
A1: 天峨县林朵林场新场部危改房AB栋2018年度电梯维护费收缴情况登记表
A2: 编制部门：天峨县林朵林场计划财务科 | O2: 单位：元
A3: 编号 | B3: 房号 | C3: 原户主 | D3: 上年余额（+）或欠交（-） | E3: 1月已交 | F3: 2月已交 | G3: 3月已交 | H3: 4月已交 | I3: 5月已交 | J3: 6月已交 | K3: 7月已交 | L3: 8月已交 | M3: 9月已交 | N3: 10月已交 | O3: 11月已交 | P3: 12月已交 | Q3: 本年余额（+）或欠交（-）
A4: 1 | B4: A1801 | C4: 韦贞鸾 | Q4: =D4+E4+F4+G4+H4+I4+J4+K4+L4+M4+N4+O4+P4 -> 0
A5: 2 | B5: A1802 | C5: 杨桂玉 | Q5: =D5+E5+F5+G5+H5+I5+J5+K5+L5+M5+N5+O5+P5 -> 0
A6: 3 | B6: A1803 | C6: 胡远必 | Q6: =D6+E6+F6+G6+H6+I6+J6+K6+L6+M6+N6+O6+P6 -> 0
A7: 4 | B7: A1804 | C7: 梁小凤 | Q7: =D7+E7+F7+G7+H7+I7+J7+K7+L7+M7+N7+O7+P7 -> 0
A8: 5 | B8: A1701 | C8: 陈巧玲 | Q8: =D8+E8+F8+G8+H8+I8+J8+K8+L8+M8+N8+O8+P8 -> 0
A9: 6 | B9: A1702 | C9: 周凤琼 | Q9: =D9+E9+F9+G9+H9+I9+J9+K9+L9+M9+N9+O9+P9 -> 0
A10: 7 | B10: A1703 | C10: 班华钊 | Q10: =D10+E10+F10+G10+H10+I10+J10+K10+L10+M10+N10+O10+P10 -> 0
A11: 8 | B11: A1704 | C11: 孙慧芳 | Q11: =D11+E11+F11+G11+H11+I11+J11+K11+L11+M11+N11+O11+P11 -> 0
A12: 9 | B12: A1601 | C12: 赵花萄 | Q12: =D12+E12+F12+G12+H12+I12+J12+K12+L12+M12+N12+O12+P12 -> 0
A13: 10 | B13: A1602 | C13: 韦玉林 | Q13: =D13+E13+F13+G13+H13+I13+J13+K13+L13+M13+N13+O13+P13 -> 0
A14: 11 | B14: A1603 | C14: 李祖勋 | Q14: =D14+E14+F14+G14+H14+I14+J14+K14+L14+M14+N14+O14+P14 -> 0
A15: 12 | B15: A1604 | C15: 马尚军 | Q15: =D15+E15+F15+G15+H15+I15+J15+K15+L15+M15+N15+O15+P15 -> 0
... A127: 124 | B127: B404 | C127: 周冬梅 | Q127: =D127+E127+F127+G127+H127+I127+J127+K127+L127+M127+N127+O127+P127 -> 0
A128: 125 | B128: B301 | Q128: =D128+E128+F128+G128+H128+I128+J128+K128+L128+M128+N128+O128+P128 -> 0
A129: 126 | B129: B302 | C129: 田明川 | Q129: =D129+E129+F129+G129+H129+I129+J129+K129+L129+M129+N129+O129+P129 -> 0
A130: 127 | B130: B303 | C130: 韦仕斌 | Q130: =D130+E130+F130+G130+H130+I130+J130+K130+L130+M130+N130+O130+P130 -> 0
A131: 128 | B131: B304 | C131: 韦光伟 | Q131: =D131+E131+F131+G131+H131+I131+J131+K131+L131+M131+N131+O131+P131 -> 0
A132: 129 | C132: 合计 | D132: =SUM(D4:D131) -> 0 | E132: =SUM(E4:E131) -> 0 | F132: =SUM(F4:F131) -> 0 | G132: =SUM(G4:G131) -> 0 | H132: =SUM(H4:H131) -> 0 | I132: =SUM(I4:I131) -> 0 | J132: =SUM(J4:J131) -> 0 | K132: =SUM(K4:K131) -> 0 | ... Q132: =SUM(Q4:Q131) -> 0
D133: 19746

Sheet 2019年 
A1: 天峨县林朵林场新场部危改房AB栋2019年度电梯维护费收缴情况登记表
A2: 编制部门：天峨县林朵林场计划财务科 | O2: 单位：元
A3: 编号 | B3: 房号 | C3: 原户主 | D3: 上年余额（+）或欠交（-） | E3: 1月已交 | F3: 2月已交 | G3: 3月已交 | H3: 4月已交 | I3: 5月已交 | J3: 6月已交 | K3: 7月已交 | L3: 8月已交 | M3: 9月已交 | N3: 10月已交 | O3: 11月已交 | P3: 12月已交 | Q3: 本年余额（+）或欠交（-）
A4: 1 | B4: A1801 | C4: 韦贞鸾 | H4: 162.38 | N4: 235.86 | Q4: =D4+E4+F4+G4+H4+I4+J4+K4+L4+M4+N4+O4+P4 -> 398.24
A5: 2 | B5: A1802 | C5: 杨桂玉 | H5: 162.38 | N5: 235.86 | Q5: =D5+E5+F5+G5+H5+I5+J5+K5+L5+M5+N5+O5+P5 -> 398.24
A6: 3 | B6: A1803 | C6: 胡远必 | F6: 162.38 | Q6: =D6+E6+F6+G6+H6+I6+J6+K6+L6+M6+N6+O6+P6 -> 162.38
A7: 4 | B7: A1804 | C7: 梁小凤 | H7: 162.38 | N7: 235.86 | Q7: =D7+E7+F7+G7+H7+I7+J7+K7+L7+M7+N7+O7+P7 -> 398.24
A8: 5 | B8: A1701 | C8: 陈巧玲 | F8: 162.38 | O8: 235.86 | Q8: =D8+E8+F8+G8+H8+I8+J8+K8+L8+M8+N8+O8+P8 -> 398.24
A9: 6 | B9: A1702 | C9: 周凤琼 | H9: 162.38 | O9: 235.86 | Q9: =D9+E9+F9+G9+H9+I9+J9+K9+L9+M9+N9+O9+P9 -> 398.24
A10: 7 | B10: A1703 | C10: 班华钊 | F10: 162.38 | O10: 235.86 | Q10: =D10+E10+F10+G10+H10+I10+J10+K10+L10+M10+N10+O10+P10 -> 398.24
A11: 8 | B11: A1704 | C11: 孙慧芳 | F11: 162.38 | N11: 235.86 | Q11: =D11+E11+F11+G11+H11+I11+J11+K11+L11+M11+N11+O11+P11 -> 398.24
A12: 9 | B12: A1601 | C12: 赵花萄 | I12: 162.38 | Q12: =D12+E12+F12+G12+H12+I12+J12+K12+L12+M12+N12+O12+P12 -> 162.38
A13: 10 | B13: A1602 | C13: 韦玉林 | Q13: =D13+E13+F13+G13+H13+I13+J13+K13+L13+M13+N13+O13+P13 -> 0
A14: 11 | B14: A1603 | C14: 李祖勋 | Q14: =D14+E14+F14+G14+H14+I14+J14+K14+L14+M14+N14+O14+P14 -> 0
A15: 12 | B15: A1604 | C15: 马尚军 | E15: 162.38 | N15: 235.86 | Q15: =D15+E15+F15+G15+H15+I15+J15+K15+L15+M15+N15+O15+P15 -> 398.24
A16: 13 | B16: A1501 | C16: 杨凤英 | E16: 162.38 | N16: 235.86 | Q16: =D16+E16+F16+G16+H16+I16+J16+K16+L16+M16+N16+O16+P16 -> 398.24
A17: 14 | B17: A1502 | C17: 陈曙林 | Q17: =D17+E17+F17+G17+H17+I17+J17+K17+L17+M17+N17+O17+P17 -> 0
A18: 15 | B18: A1503 | C18: 韦月鸾 | Q18: =D18+E18+F18+G18+H18+I18+J18+K18+L18+M18+N18+O18+P18 -> 0
A19: 16 | B19: A1504 | C19: 方焕忠 | E19: 162.38 | N19: 235.86 | Q19: =D19+E19+F19+G19+H19+I19+J19+K19+L19+M19+N19+O19+P19 -> 398.24
A20: 17 | B20: A1401 | C20: 李向农 | H20: 163 | P20: 235.24 | Q20: =D20+E20+F20+G20+H20+I20+J20+K20+L20+M20+N20+O20+P20 -> 398.24
A21: 18 | B21: A1402 | C21: 邓扬静 | H21: 161.38 | P21: 235.86 | Q21: =D21+E21+F21+G21+H21+I21+J21+K21+L21+M21+N21+O21+P21 -> 397.24
A22: 19 | B22: A1403 | C22: 黄光龙 | H22: 162.38 | N22: 235.86 | Q22: =D22+E22+F22+G22+H22+I22+J22+K22+L22+M22+N22+O22+P22 -> 398.24
A23: 20 | B23: A1404 | C23: 杨光权 | H23: 162.38 | N23: 235.86 | Q23: =D23+E23+F23+G23+H23+I23+J23+K23+L23+M23+N23+O23+P23 -> 398.24
A24: 21 | B24: A1301 | C24: 吴胜斌 | H24: 162.38 | Q24: =D24+E24+F24+G24+H24+I24+J24+K24+L24+M24+N24+O24+P24 -> 162.38
A25: 22 | B25: A1302 | C25: 韦献萍 | H25: 162.38 | O25: 235.86 | Q25: =D25+E25+F25+G25+H25+I25+J25+K25+L25+M25+N25+O25+P25 -> 398.24
A26: 23 | B26: A1303 | C26: 黄汉冕 | H26: 162.38 | P26: 235.86 | Q26: =D26+E26+F26+G26+H26+I26+J26+K26+L26+M26+N26+O26+P26 -> 398.24
A27: 24 | B27: A1304 | C27: 梁艳红 | I27: 162.38 | Q27: =D27+E27+F27+G27+H27+I27+J27+K27+L27+M27+N27+O27+P27 -> 162.38
A28: 25 | B28: A1201 | C28: 索邦卫 | H28: 162.38 | O28: 235.86 | Q28: =D28+E28+F28+G28+H28+I28+J28+K28+L28+M28+N28+O28+P28 -> 398.24
A29: 26 | B29: A1202 | C29: 韦竹珍 | H29: 162.38 | P29: 235.86 | Q29: =D29+E29+F29+G29+H29+I29+J29+K29+L29+M29+N29+O29+P29 -> 398.24
A30: 27 | B30: A1203 | C30: 冉光新 | H30: 162.5 | Q30: =D30+E30+F30+G30+H30+I30+J30+K30+L30+M30+N30+O30+P30 -> 162.5
A31: 28 | B31: A1204 | C31: 彭鸣忠 | I31: 162.38 | Q31: =D31+E31+F31+G31+H31+I31+J31+K31+L31+M31+N31+O31+P31 -> 162.38
A32: 29 | B32: A1103 | C32: 李莎莎 | H32: 162.38 | O32: 235.86 | Q32: =D32+E32+F32+G32+H32+I32+J32+K32+L32+M32+N32+O32+P32 -> 398.24
A33: 30 | B33: A1104 | C33: 陈臻慧 | H33: 162.38 | N33: 235.86 | Q33: =D33+E33+F33+G33+H33+I33+J33+K33+L33+M33+N33+O33+P33 -> 398.24
A34: 31 | B34: A1101 | C34: 吴爱叶 | H34: 162.38 | N34: 235.86 | Q34: =D34+E34+F34+G34+H34+I34+J34+K34+L34+M34+N34+O34+P34 -> 398.24
A35: 32 | B35: A1102 | C35: 岑丽娟 | Q35: =D35+E35+F35+G35+H35+I35+J35+K35+L35+M35+N35+O35+P35 -> 0
A36: 33 | B36: A1001 | C36: 黄敬财 | Q36: =D36+E36+F36+G36+H36+I36+J36+K36+L36+M36+N36+O36+P36 -> 0
A37: 34 | B37: A1002 | C37: 韦永 | H37: 163.28 | N37: 234.96 | Q37: =D37+E37+F37+G37+H37+I37+J37+K37+L37+M37+N37+O37+P37 -> 398.24
A38: 35 | B38: A1003 | C38: 黄国华 | E38: 162.38 | O38: 235.86 | Q38: =D38+E38+F38+G38+H38+I38+J38+K38+L38+M38+N38+O38+P38 -> 398.24
A39: 36 | B39: A1004 | C39: 樊红 | H39: 162.38 | N39: 235.86 | Q39: =D39+E39+F39+G39+H39+I39+J39+K39+L39+M39+N39+O39+P39 -> 398.24
A40: 37 | B40: A901 | C40: 吴荣庆 | H40: 162.38 | N40: 235.86 | Q40: =D40+E40+F40+G40+H40+I40+J40+K40+L40+M40+N40+O40+P40 -> 398.24
...

Sheet 2020年 
A1: 天峨县林朵林场新场部危改房AB栋2020年度电梯维护费收缴情况登记表
A2: 编制部门：天峨县林朵林场计划财务科 | O2: 单位：元
A3: 编号 | B3: 房号 | C3: 原户主 | D3: 上年余额（+）或欠交（-） | E3: 1月已交 | F3: 2月已交 | G3: 3月已交 | H3: 4月已交 | I3: 5月已交 | J3: 6月已交 | K3: 7月已交 | L3: 8月已交 | M3: 9月已交 | N3: 10月已交 | O3: 11月已交 | P3: 12月已交 | Q3: 本年余额（+）或欠交（-）
A4: 1 | B4: A1801 | C4: 韦贞鸾 | G4: 320.26 | L4: 109.92 | Q4: =D4+E4+F4+G4+H4+I4+J4+K4+L4+M4+N4+O4+P4 -> 430.18
A5: 2 | B5: A1802 | C5: 杨桂玉 | G5: 321 | M5: 109.92 | Q5: =D5+E5+F5+G5+H5+I5+J5+K5+L5+M5+N5+O5+P5 -> 430.92
A6: 3 | B6: A1803 | C6: 胡远必 | G6: 556.12 | K6: 109.92 | Q6: =D6+E6+F6+G6+H6+I6+J6+K6+L6+M6+N6+O6+P6 -> 666.04
A7: 4 | B7: A1804 | C7: 梁小凤 | G7: 320.26 | K7: 109.92 | Q7: =D7+E7+F7+G7+H7+I7+J7+K7+L7+M7+N7+O7+P7 -> 430.18
A8: 5 | B8: A1701 | C8: 陈巧玲 | H8: 320.26 | K8: 109.92 | Q8: =D8+E8+F8+G8+H8+I8+J8+K8+L8+M8+N8+O8+P8 -> 430.18
A9: 6 | B9: A1702 | C9: 周凤琼 | G9: 320.26 | K9: 109.92 | Q9: =D9+E9+F9+G9+H9+I9+J9+K9+L9+M9+N9+O9+P9 -> 430.18
A10: 7 | B10: A1703 | C10: 班华钊 | L10: 109.92 | Q10: =D10+E10+F10+G10+H10+I10+J10+K10+L10+M10+N10+O10+P10 -> 109.92
A11: 8 | B11: A1704 | C11: 孙慧芳 | G11: 320.26 | K11: 109.92 | Q11: =D11+E11+F11+G11+H11+I11+J11+K11+L11+M11+N11+O11+P11 -> 430.18
A12: 9 | B12: A1601 | C12: 赵花萄 | H12: 556.12 | L12: 109.92 | Q12: =D12+E12+F12+G12+H12+I12+J12+K12+L12+M12+N12+O12+P12 -> 666.04
A13: 10 | B13: A1602 | C13: 韦玉林 | Q13: =D13+E13+F13+G13+H13+I13+J13+K13+L13+M13+N13+O13+P13 -> 0
A14: 11 | B14: A1603 | C14: 李祖勋 | Q14: =D14+E14+F14+G14+H14+I14+J14+K14+L14+M14+N14+O14+P14 -> 0
A15: 12 | B15: A1604 | C15: 马尚军 | G15: 320.26 | J15: 109.92 | Q15: =D15+E15+F15+G15+H15+I15+J15+K15+L15+M15+N15+O15+P15 -> 430.18
A16: 13 | B16: A1501 | C16: 杨凤英 | G16: 320.2 | K16: 109.92 | P16: 109.92 | Q16: =D16+E16+F16+G16+H16+I16+J16+K16+L16+M16+N16+O16+P16 -> 540.04
A17: 14 | B17: A1502 | C17: 陈曙林 | Q17: =D17+E17+F17+G17+H17+I17+J17+K17+L17+M17+N17+O17+P17 -> 0
A18: 15 | B18: A1503 | C18: 韦月鸾 | Q18: =D18+E18+F18+G18+H18+I18+J18+K18+L18+M18+N18+O18+P18 -> 0
A19: 16 | B19: A1504 | C19: 方焕忠 | G19: 320.2 | K19: 109.92 | Q19: =D19+E19+F19+G19+H19+I19+J19+K19+L19+M19+N19+O19+P19 -> 430.12
A20: 17 | B20: A1401 | C20: 李向农 | I20: 320.26 | L20: 109.92 | Q20: =D20+E20+F20+G20+H20+I20+J20+K20+L20+M20+N20+O20+P20 -> 430.18
A21: 18 | B21: A1402 | C21: 邓扬静 | I21: 321.26 | N21: 109.92 | Q21: =D21+E21+F21+G21+H21+I21+J21+K21+L21+M21+N21+O21+P21 -> 431.18
A22: 19 | B22: A1403 | C22: 黄光龙 | G22: 320.26 | K22: 109.92 | M22: 109.92 | Q22: =D22+E22+F22+G22+H22+I22+J22+K22+L22+M22+N22+O22+P22 -> 540.1
A23: 20 | B23: A1404 | C23: 杨光权 | G23: 320.26 | K23: 109.92 | Q23: =D23+E23+F23+G23+H23+I23+J23+K23+L23+M23+N23+O23+P23 -> 430.18
A24: 21 | B24: A1301 | C24: 吴胜斌 | H24: 556.12 | K24: 109.92 | Q24: =D24+E24+F24+G24+H24+I24+J24+K24+L24+M24+N24+O24+P24 -> 666.04
A25: 22 | B25: A1302 | C25: 韦献萍 | H25: 320.26 | O25: 109.92 | Q25: =D25+E25+F25+G25+H25+I25+J25+K25+L25+M25+N25+O25+P25 -> 430.18
A26: 23 | B26: A1303 | C26: 黄汉冕 | I26: 320.26 | P26: 109.92 | Q26: =D26+E26+F26+G26+H26+I26+J26+K26+L26+M26+N26+O26+P26 -> 430.18
A27: 24 | B27: A1304 | C27: 梁艳红 | H27: 556.2 | P27: 109.92 | Q27: =D27+E27+F27+G27+H27+I27+J27+K27+L27+M27+N27+O27+P27 -> 666.12
A28: 25 | B28: A1201 | C28: 索邦卫 | H28: 320.26 | M28: 109.92 | Q28: =D28+E28+F28+G28+H28+I28+J28+K28+L28+M28+N28+O28+P28 -> 430.18
A29: 26 | B29: A1202 | C29: 韦竹珍 | K29: 109.92 | Q29: =D29+E29+F29+G29+H29+I29+J29+K29+L29+M29+N29+O29+P29 -> 109.92
A30: 27 | B30: A1203 | C30: 冉光新 | G30: 235.74 | K30: 109.92 | Q30: =D30+E30+F30+G30+H30+I30+J30+K30+L30+M30+N30+O30+P30 -> 345.66
A31: 28 | B31: A1204 | C31: 彭鸣忠 | I31: 556.12 | M31: 109.92 | Q31: =D31+E31+F31+G31+H31+I31+J31+K31+L31+M31+N31+O31+P31 -> 666.04
A32: 29 | B32: A1103 | C32: 李莎莎 | G32: 320.26 | K32: 109.92 | Q32: =D32+E32+F32+G32+H32+I32+J32+K32+L32+M32+N32+O32+P32 -> 430.18
A33: 30 | B33: A1104 | C33: 陈臻慧 | G33: 320.26 | L33: 109.92 | Q33: =D33+E33+F33+G33+H33+I33+J33+K33+L33+M33+N33+O33+P33 -> 430.18
A34: 31 | B34: A1101 | C34: 吴爱叶 | G34: 320.26 | P34: 109.92 | Q34: =D34+E34+F34+G34+H34+I34+J34+K34+L34+M34+N34+O34+P34 -> 430.18
A35: 32 | B35: A1102 | C35: 岑丽娟 | P35: 109.92 | Q35: =D35+E35+F35+G35+H35+I35+J35+K35+L35+M35+N35+O35+P35 -> 109.92
A36: 33 | B36: A1001 | C36: 黄敬财 | Q36: =D36+E36+F36+G36+H36+I36+J36+K36+L36+M36+N36+O36+P36 -> 0
A37: 34 | B37: A1002 | C37: 韦永 | G37: 320.26 | L37: 109.92 | Q37: =D37+E37+F37+G37+H37+I37+J37+K37+L37+M37+N37+O37+P37 -> 430.18
A38: 35 | B38: A1003 | C38: 黄国华 | H38: 320.26 | L38: 109.92 | Q38: =D38+E38+F38+G38+H38+I38+J38+K38+L38+M38+N38+O38+P38 -> 430.18
A39: 36 | B39: A1004 | C39: 樊红 | G39: 320.26 | P39: 109.92 | Q39: =D39+E39+F39+G39+H39+I39+J39+K39+L39+M39+N39+O39+P39 -> 430.18
A40: 37 | B40: A901 | C40: 吴荣庆 | G40: 320.26 | K40: 109.92 | L40: 109.92 | Q40: =D40+E40+F40+G40+H40+I40+J40+K40+L40+M40+N40+O40+P40 -> 540.1
...

Sheet 2021年 
A1: 天峨县林朵林场新场部危改房AB栋2021年度电梯维护费收缴情况登记表
A2: 编制部门：天峨县林朵林场计划财务科 | O2: 单位：元
A3: 编号 | B3: 房号 | C3: 原户主 | D3: 上年余额（+）或欠交（-） | E3: 1月已交 | F3: 2月已交 | G3: 3月已交 | H3: 4月已交 | I3: 5月已交 | J3: 6月已交 | K3: 7月已交 | L3: 8月已交 | M3: 9月已交 | N3: 10月已交 | O3: 11月已交 | P3: 12月已交 | Q3: 本年余额（+）或欠交（-）
A4: 1 | B4: A1801 | C4: 韦贞鸾 | G4: 256.31 | L4: 168.6 | Q4: =D4+E4+F4+G4+H4+I4+J4+K4+L4+M4+N4+O4+P4 -> 424.91
A5: 2 | B5: A1802 | C5: 杨桂玉 | G5: 255.57 | K5: 168.6 | P5: 89.76 | Q5: =D5+E5+F5+G5+H5+I5+J5+K5+L5+M5+N5+O5+P5 -> 513.93
A6: 3 | B6: A1803 | C6: 胡远必 | G6: 256.31 | K6: 168.6 | P6: 89.76 | Q6: =D6+E6+F6+G6+H6+I6+J6+K6+L6+M6+N6+O6+P6 -> 514.67
A7: 4 | B7: A1804 | C7: 梁小凤 | G7: 256.31 | K7: 168.6 | Q7: =D7+E7+F7+G7+H7+I7+J7+K7+L7+M7+N7+O7+P7 -> 424.91
A8: 5 | B8: A1701 | C8: 陈巧玲 | G8: 256.31 | L8: 168.6 | Q8: =D8+E8+F8+G8+H8+I8+J8+K8+L8+M8+N8+O8+P8 -> 424.91
A9: 6 | B9: A1702 | C9: 周凤琼 | G9: 256.31 | K9: 168.6 | P9: 89.76 | Q9: =D9+E9+F9+G9+H9+I9+J9+K9+L9+M9+N9+O9+P9 -> 514.67
A10: 7 | B10: A1703 | C10: 班华钊 | G10: =472.1+104.47 -> 576.57 | K10: 168.6 | P10: 89.76 | Q10: =D10+E10+F10+G10+H10+I10+J10+K10+L10+M10+N10+O10+P10 -> 834.93
A11: 8 | B11: A1704 | C11: 孙慧芳 | G11: 256.31 | K11: 168.6 | P11: 89.76 | Q11: =D11+E11+F11+G11+H11+I11+J11+K11+L11+M11+N11+O11+P11 -> 514.67
A12: 9 | B12: A1601 | C12: 赵花萄 | G12: 256.31 | P12: 258.36 | Q12: =D12+E12+F12+G12+H12+I12+J12+K12+L12+M12+N12+O12+P12 -> 514.67
A13: 10 | B13: A1602 | C13: 韦玉林 | I13: 200 | K13: 256.31 | P13: 168.6 | Q13: =D13+E13+F13+G13+H13+I13+J13+K13+L13+M13+N13+O13+P13 -> 624.91
A14: 11 | B14: A1603 | C14: 李祖勋 | Q14: =D14+E14+F14+G14+H14+I14+J14+K14+L14+M14+N14+O14+P14 -> 0
A15: 12 | B15: A1604 | C15: 马尚军 | H15: 256.31 | K15: 168.6 | P15: 89.76 | Q15: =D15+E15+F15+G15+H15+I15+J15+K15+L15+M15+N15+O15+P15 -> 514.67
A16: 13 | B16: A1501 | C16: 杨凤英 | G16: 146.45 | K16: 168.6 | P16: 89.76 | Q16: =D16+E16+F16+G16+H16+I16+J16+K16+L16+M16+N16+O16+P16 -> 404.81
A17: 14 | B17: A1502 | C17: 陈曙林 | Q17: =D17+E17+F17+G17+H17+I17+J17+K17+L17+M17+N17+O17+P17 -> 0
A18: 15 | B18: A1503 | C18: 韦月鸾 | Q18: =D18+E18+F18+G18+H18+I18+J18+K18+L18+M18+N18+O18+P18 -> 0
A19: 16 | B19: A1504 | C19: 方焕忠 | G19: 256.37 | K19: 168.6 | P19: 89.76 | Q19: =D19+E19+F19+G19+H19+I19+J19+K19+L19+M19+N19+O19+P19 -> 514.73
A20: 17 | B20: A1401 | C20: 李向农 | H20: 256.31 | K20: 168.6 | P20: 89.76 | Q20: =D20+E20+F20+G20+H20+I20+J20+K20+L20+M20+N20+O20+P20 -> 514.67
A21: 18 | B21: A1402 | C21: 邓扬静 | G21: 146.39 | P21: 258.36 | Q21: =D21+E21+F21+G21+H21+I21+J21+K21+L21+M21+N21+O21+P21 -> 404.75
A22: 19 | B22: A1403 | C22: 黄光龙 | G22: 256.31 | K22: 168.6 | Q22: =D22+E22+F22+G22+H22+I22+J22+K22+L22+M22+N22+O22+P22 -> 424.91
A23: 20 | B23: A1404 | C23: 杨光权 | G23: 256.31 | K23: 168.6 | Q23: =D23+E23+F23+G23+H23+I23+J23+K23+L23+M23+N23+O23+P23 -> 424.91
A24: 21 | B24: A1301 | C24: 吴胜斌 | G24: 256.31 | K24: 168.6 | P24: 89.76 | Q24: =D24+E24+F24+G24+H24+I24+J24+K24+L24+M24+N24+O24+P24 -> 514.67
A25: 22 | B25: A1302 | C25: 韦献萍 | G25: 256.31 | K25: 168.6 | P25: 89.76 | Q25: =D25+E25+F25+G25+H25+I25+J25+K25+L25+M25+N25+O25+P25 -> 514.67
A26: 23 | B26: A1303 | C26: 黄汉冕 | K26: 256.31 | P26: 258.36 | Q26: =D26+E26+F26+G26+H26+I26+J26+K26+L26+M26+N26+O26+P26 -> 514.67
A27: 24 | B27: A1304 | C27: 梁艳红 | K27: 256.31 | P27: 258.36 | Q27: =D27+E27+F27+G27+H27+I27+J27+K27+L27+M27+N27+O27+P27 -> 514.67
A28: 25 | B28: A1201 | C28: 索邦卫 | G28: 256.31 | K28: 168.6 | P28: 89.76 | Q28: =D28+E28+F28+G28+H28+I28+J28+K28+L28+M28+N28+O28+P28 -> 514.67
A29: 26 | B29: A1202 | C29: 韦竹珍 | G29: 576.57 | P29: 258.36 | Q29: =D29+E29+F29+G29+H29+I29+J29+K29+L29+M29+N29+O29+P29 -> 834.93
A30: 27 | B30: A1203 | C30: 冉光新 | G30: 256.31 | L30: 168.6 | P30: 89.76 | Q30: =D30+E30+F30+G30+H30+I30+J30+K30+L30+M30+N30+O30+P30 -> 514.67
A31: 28 | B31: A1204 | C31: 彭鸣忠 | K31: 256.31 | P31: 258.36 | Q31: =D31+E31+F31+G31+H31+I31+J31+K31+L31+M31+N31+O31+P31 -> 514.67
A32: 29 | B32: A1103 | C32: 李莎莎 | G32: 256.31 | K32: 168.6 | P32: 89.76 | Q32: =D32+E32+F32+G32+H32+I32+J32+K32+L32+M32+N32+O32+P32 -> 514.67
A33: 30 | B33: A1104 | C33: 陈臻慧 | G33: 256.31 | K33: 168.6 | Q33: =D33+E33+F33+G33+H33+I33+J33+K33+L33+M33+N33+O33+P33 -> 424.91
A34: 31 | B34: A1101 | C34: 吴爱叶 | H34: 256.31 | L34: 168.6 | Q34: =D34+E34+F34+G34+H34+I34+J34+K34+L34+M34+N34+O34+P34 -> 424.91
A35: 32 | B35: A1102 | C35: 岑丽娟 | G35: 256.31 | K35: 168.6 | P35: 89.76 | Q35: =D35+E35+F35+G35+H35+I35+J35+K35+L35+M35+N35+O35+P35 -> 514.67
A36: 33 | B36: A1001 | C36: 黄敬财 | Q36: =D36+E36+F36+G36+H36+I36+J36+K36+L36+M36+N36+O36+P36 -> 0
A37: 34 | B37: A1002 | C37: 韦永 | G37: 256.31 | K37: 168.6 | P37: 89.76 | Q37: =D37+E37+F37+G37+H37+I37+J37+K37+L37+M37+N37+O37+P37 -> 514.67
A38: 35 | B38: A1003 | C38: 黄国华 | G38: 256.31 | K38: 168.6 | P38: 89.76 | Q38: =D38+E38+F38+G38+H38+I38+J38+K38+L38+M38+N38+O38+P38 -> 514.67
A39: 36 | B39: A1004 | C39: 樊红 | G39: 256.31 | K39: 168.6 | P39: 89.76 | Q39: =D39+E39+F39+G39+H39+I39+J39+K39+L39+M39+N39+O39+P39 -> 514.67
A40: 37 | B40: A901 | C40: 吴荣庆 | G40: 256.31 | K40: 168.6 | P40: 89.76 | Q40: =D40+E40+F40+G40+H40+I40+J40+K40+L40+M40+N40+O40+P40 -> 514.67
...

Sheet 2022年 
A1: 天峨县林朵林场新场部危改房AB栋2022年度电梯维护费收缴情况登记表
A2: 编制部门：天峨县林朵林场计划财务科 | O2: 单位：元
A3: 编号 | B3: 房号 | C3: 原户主 | D3: 上年余额（+）或欠交（-） | E3: 1月已交 | F3: 2月已交 | G3: 3月已交 | H3: 4月已交 | I3: 5月已交 | J3: 6月已交 | K3: 7月已交 | L3: 8月已交 | M3: 9月已交 | N3: 10月已交 | O3: 11月已交 | P3: 12月已交 | Q3: 本年余额（+）或欠交（-）
A4: 1 | B4: A1801 | C4: 韦贞鸾 | F4: 83.64 | G4: 6.15 | J4: 133.52 | Q4: =D4+E4+F4+G4+H4+I4+J4+K4+L4+M4+N4+O4+P4 -> 223.31
A5: 2 | B5: A1802 | C5: 杨桂玉 | J5: 133.52 | Q5: =D5+E5+F5+G5+H5+I5+J5+K5+L5+M5+N5+O5+P5 -> 133.52
A6: 3 | B6: A1803 | C6: 胡远必 | K6: 133.52 | Q6: =D6+E6+F6+G6+H6+I6+J6+K6+L6+M6+N6+O6+P6 -> 133.52
A7: 4 | B7: A1804 | C7: 梁小凤 | F7: 89.79 | Q7: =D7+E7+F7+G7+H7+I7+J7+K7+L7+M7+N7+O7+P7 -> 89.79
A8: 5 | B8: A1701 | C8: 陈巧玲 | E8: 89.79 | J8: 133.52 | Q8: =D8+E8+F8+G8+H8+I8+J8+K8+L8+M8+N8+O8+P8 -> 223.31
A9: 6 | B9: A1702 | C9: 周凤琼 | K9: 133.52 | Q9: =D9+E9+F9+G9+H9+I9+J9+K9+L9+M9+N9+O9+P9 -> 133.52
A10: 7 | B10: A1703 | C10: 班华钊 | J10: 133.52 | Q10: =D10+E10+F10+G10+H10+I10+J10+K10+L10+M10+N10+O10+P10 -> 133.52
A11: 8 | B11: A1704 | C11: 孙慧芳 | Q11: =D11+E11+F11+G11+H11+I11+J11+K11+L11+M11+N11+O11+P11 -> 0
A12: 9 | B12: A1601 | C12: 赵花萄 | J12: 133.52 | Q12: =D12+E12+F12+G12+H12+I12+J12+K12+L12+M12+N12+O12+P12 -> 133.52
A13: 10 | B13: A1602 | C13: 韦玉林 | F13: 89.79 | Q13: =D13+E13+F13+G13+H13+I13+J13+K13+L13+M13+N13+O13+P13 -> 89.79
A14: 11 | B14: A1603 | C14: 李祖勋 | E14: 89.79 | K14: 133.52 | Q14: =D14+E14+F14+G14+H14+I14+J14+K14+L14+M14+N14+O14+P14 -> 223.31
A15: 12 | B15: A1604 | C15: 马尚军 | J15: 133.52 | Q15: =D15+E15+F15+G15+H15+I15+J15+K15+L15+M15+N15+O15+P15 -> 133.52
A16: 13 | B16: A1501 | C16: 杨凤英 | J16: 133.52 | Q16: =D16+E16+F16+G16+H16+I16+J16+K16+L16+M16+N16+O16+P16 -> 133.52
A17: 14 | B17: A1502 | C17: 陈曙林 | Q17: =D17+E17+F17+G17+H17+I17+J17+K17+L17+M17+N17+O17+P17 -> 0
A18: 15 | B18: A1503 | C18: 韦月鸾 | Q18: =D18+E18+F18+G18+H18+I18+J18+K18+L18+M18+N18+O18+P18 -> 0
A19: 16 | B19: A1504 | C19: 方焕忠 | J19: 133.52 | Q19: =D19+E19+F19+G19+H19+I19+J19+K19+L19+M19+N19+O19+P19 -> 133.52
A20: 17 | B20: A1401 | C20: 李向农 | K20: 133.52 | Q20: =D20+E20+F20+G20+H20+I20+J20+K20+L20+M20+N20+O20+P20 -> 133.52
A21: 18 | B21: A1402 | C21: 邓扬静 | J21: 133.52 | Q21: =D21+E21+F21+G21+H21+I21+J21+K21+L21+M21+N21+O21+P21 -> 133.52
A22: 19 | B22: A1403 | C22: 黄光龙 | E22: 89.79 | L22: 133.52 | Q22: =D22+E22+F22+G22+H22+I22+J22+K22+L22+M22+N22+O22+P22 -> 223.31
A23: 20 | B23: A1404 | C23: 杨光权 | E23: 89.79 | K23: 133.52 | Q23: =D23+E23+F23+G23+H23+I23+J23+K23+L23+M23+N23+O23+P23 -> 223.31
A24: 21 | B24: A1301 | C24: 吴胜斌 | J24: 133.52 | Q24: =D24+E24+F24+G24+H24+I24+J24+K24+L24+M24+N24+O24+P24 -> 133.52
A25: 22 | B25: A1302 | C25: 韦献萍 | L25: 133.52 | Q25: =D25+E25+F25+G25+H25+I25+J25+K25+L25+M25+N25+O25+P25 -> 133.52
A26: 23 | B26: A1303 | C26: 黄汉冕 | O26: 133.52 | Q26: =D26+E26+F26+G26+H26+I26+J26+K26+L26+M26+N26+O26+P26 -> 133.52
A27: 24 | B27: A1304 | C27: 梁艳红 | Q27: =D27+E27+F27+G27+H27+I27+J27+K27+L27+M27+N27+O27+P27 -> 0
A28: 25 | B28: A1201 | C28: 索邦卫 | J28: 133.52 | Q28: =D28+E28+F28+G28+H28+I28+J28+K28+L28+M28+N28+O28+P28 -> 133.52
A29: 26 | B29: A1202 | C29: 韦竹珍 | K29: 133.52 | Q29: =D29+E29+F29+G29+H29+I29+J29+K29+L29+M29+N29+O29+P29 -> 133.52
A30: 27 | B30: A1203 | C30: 冉光新 | J30: 129.97 | K30: 3.55 | Q30: =D30+E30+F30+G30+H30+I30+J30+K30+L30+M30+N30+O30+P30 -> 133.52
A31: 28 | B31: A1204 | C31: 彭鸣忠 | Q31: =D31+E31+F31+G31+H31+I31+J31+K31+L31+M31+N31+O31+P31 -> 0
A32: 29 | B32: A1103 | C32: 李莎莎 | J32: 133.52 | Q32: =D32+E32+F32+G32+H32+I32+J32+K32+L32+M32+N32+O32+P32 -> 133.52
A33: 30 | B33: A1104 | C33: 陈臻慧 | G33: 89.79 | K33: 133.52 | Q33: =D33+E33+F33+G33+H33+I33+J33+K33+L33+M33+N33+O33+P33 -> 223.31
A34: 31 | B34: A1101 | C34: 吴爱叶 | E34: 89.76 | J34: 110 | Q34: =D34+E34+F34+G34+H34+I34+J34+K34+L34+M34+N34+O34+P34 -> 199.76
A35: 32 | B35: A1102 | C35: 岑丽娟 | J35: 133.52 | Q35: =D35+E35+F35+G35+H35+I35+J35+K35+L35+M35+N35+O35+P35 -> 133.52
A36: 33 | B36: A1001 | C36: 黄敬财 | Q36: =D36+E36+F36+G36+H36+I36+J36+K36+L36+M36+N36+O36+P36 -> 0
A37: 34 | B37: A1002 | C37: 韦永 | Q37: =D37+E37+F37+G37+H37+I37+J37+K37+L37+M37+N37+O37+P37 -> 0
A38: 35 | B38: A1003 | C38: 黄国华 | J38: 133.52 | Q38: =D38+E38+F38+G38+H38+I38+J38+K38+L38+M38+N38+O38+P38 -> 133.52
A39: 36 | B39: A1004 | C39: 樊红 | J39: 133.52 | Q39: =D39+E39+F39+G39+H39+I39+J39+K39+L39+M39+N39+O39+P39 -> 133.52
A40: 37 | B40: A901 | C40: 吴荣庆 | J40: 133.52 | Q40: =D40+E40+F40+G40+H40+I40+J40+K40+L40+M40+N40+O40+P40 -> 133.52
...

Sheet 2023年 
A1: 天峨县林朵林场新场部危改房AB栋2023年度电梯维护费收缴情况登记表
A2: 编制部门：天峨县林朵林场计划财务科 | O2: 单位：元
A3: 编号 | B3: 房号 | C3: 原户主 | D3: 上年余额（+）或欠交（-） | E3: 1月已交 | F3: 2月已交 | G3: 3月已交 | H3: 4月已交 | I3: 5月已交 | J3: 6月已交 | K3: 7月已交 | L3: 8月已交 | M3: 9月已交 | N3: 10月已交 | O3: 11月已交 | P3: 12月已交 | Q3: 本年余额（+）或欠交（-）
A4: 1 | B4: A1801 | C4: 韦贞鸾 | H4: 0 | I4: 217.78 | J4: 0 | Q4: =D4+E4+F4+G4+H4+I4+J4+K4+L4+M4+N4+O4+P4 -> 217.78
A5: 2 | B5: A1802 | C5: 杨桂玉 | G5: 149.18 | H5: 0 | I5: 217.78 | J5: 0 | Q5: =D5+E5+F5+G5+H5+I5+J5+K5+L5+M5+N5+O5+P5 -> 366.96
A6: 3 | B6: A1803 | C6: 胡远必 | H6: 0 | I6: 366.96 | J6: 0 | Q6: =D6+E6+F6+G6+H6+I6+J6+K6+L6+M6+N6+O6+P6 -> 366.96
A7: 4 | B7: A1804 | C7: 梁小凤 | G7: 282.7 | H7: 0 | I7: 0 | J7: 0 | Q7: =D7+E7+F7+G7+H7+I7+J7+K7+L7+M7+N7+O7+P7 -> 282.7
A8: 5 | B8: A1701 | C8: 陈巧玲 | G8: 149.18 | H8: 0 | I8: 217.78 | J8: 0 | Q8: =D8+E8+F8+G8+H8+I8+J8+K8+L8+M8+N8+O8+P8 -> 366.96
A9: 6 | B9: A1702 | C9: 周凤琼 | G9: 149.18 | H9: 0 | I9: 217.78 | J9: 0 | Q9: =D9+E9+F9+G9+H9+I9+J9+K9+L9+M9+N9+O9+P9 -> 366.96
A10: 7 | B10: A1703 | C10: 班华钊 | G10: 149.18 | H10: 0 | I10: 217.78 | J10: 0 | Q10: =D10+E10+F10+G10+H10+I10+J10+K10+L10+M10+N10+O10+P10 -> 366.96
A11: 8 | B11: A1704 | C11: 孙慧芳 | G11: 149.18 | H11: 0 | I11: 0 | J11: 366.96 | Q11: =D11+E11+F11+G11+H11+I11+J11+K11+L11+M11+N11+O11+P11 -> 516.14
A12: 9 | B12: A1601 | C12: 赵花萄 | G12: 149.18 | H12: 0 | I12: 0 | J12: 366.96 | Q12: =D12+E12+F12+G12+H12+I12+J12+K12+L12+M12+N12+O12+P12 -> 516.14
A13: 10 | B13: A1602 | C13: 韦玉林 | H13: 0 | I13: 0 | J13: 0 | Q13: =D13+E13+F13+G13+H13+I13+J13+K13+L13+M13+N13+O13+P13 -> 0
A14: 11 | B14: A1603 | C14: 李祖勋 | G14: 149.18 | H14: 0 | I14: 0 | J14: 0 | L14: 366.96 | O14: 366.96 | Q14: =D14+E14+F14+G14+H14+I14+J14+K14+L14+M14+N14+O14+P14 -> 883.1
A15: 12 | B15: A1604 | C15: 马尚军 | G15: 149.18 | H15: 217.78 | I15: 0 | J15: 0 | L15: 0 | Q15: =D15+E15+F15+G15+H15+I15+J15+K15+L15+M15+N15+O15+P15 -> 366.96
A16: 13 | B16: A1501 | C16: 杨凤英 | G16: 149.18 | H16: 0 | I16: 217.78 | J16: 0 | L16: 0 | Q16: =D16+E16+F16+G16+H16+I16+J16+K16+L16+M16+N16+O16+P16 -> 366.96
A17: 14 | B17: A1502 | C17: 陈曙林 | H17: 0 | I17: 0 | J17: 0 | L17: 0 | Q17: =D17+E17+F17+G17+H17+I17+J17+K17+L17+M17+N17+O17+P17 -> 0
A18: 15 | B18: A1503 | C18: 韦月鸾 | H18: 0 | I18: 0 | J18: 0 | L18: 0 | Q18: =D18+E18+F18+G18+H18+I18+J18+K18+L18+M18+N18+O18+P18 -> 0
A19: 16 | B19: A1504 | C19: 方焕忠 | G19: 149.18 | H19: 0 | I19: 217.78 | J19: 0 | L19: 0 | Q19: =D19+E19+F19+G19+H19+I19+J19+K19+L19+M19+N19+O19+P19 -> 366.96
A20: 17 | B20: A1401 | C20: 李向农 | G20: 149.18 | H20: 0 | I20: 0 | J20: 0 | K20: 366.96 | L20: 0 | Q20: =D20+E20+F20+G20+H20+I20+J20+K20+L20+M20+N20+O20+P20 -> 516.14
A21: 18 | B21: A1402 | C21: 邓扬静 | G21: 149.18 | H21: 0 | I21: 217.78 | J21: 0 | K21: 0 | L21: 0 | Q21: =D21+E21+F21+G21+H21+I21+J21+K21+L21+M21+N21+O21+P21 -> 366.96
A22: 19 | B22: A1403 | C22: 黄光龙 | G22: 149.18 | H22: 0 | I22: 0 | J22: 366.96 | K22: 0 | L22: 0 | Q22: =D22+E22+F22+G22+H22+I22+J22+K22+L22+M22+N22+O22+P22 -> 516.14
A23: 20 | B23: A1404 | C23: 杨光权 | G23: 149.18 | H23: 217.78 | I23: 0 | J23: 0 | K23: 0 | L23: 0 | Q23: =D23+E23+F23+G23+H23+I23+J23+K23+L23+M23+N23+O23+P23 -> 366.96
A24: 21 | B24: A1301 | C24: 吴胜斌 | G24: 149.18 | H24: 0 | I24: 217.78 | J24: 0 | K24: 0 | L24: 0 | Q24: =D24+E24+F24+G24+H24+I24+J24+K24+L24+M24+N24+O24+P24 -> 366.96
A25: 22 | B25: A1302 | C25: 韦献萍 | H25: 0 | I25: 0 | J25: 0 | K25: 0 | L25: 500.48 | Q25: =D25+E25+F25+G25+H25+I25+J25+K25+L25+M25+N25+O25+P25 -> 500.48
A26: 23 | B26: A1303 | C26: 黄汉冕 | G26: 149.18 | H26: 0 | I26: 217.78 | J26: 0 | K26: 0 | L26: 0 | Q26: =D26+E26+F26+G26+H26+I26+J26+K26+L26+M26+N26+O26+P26 -> 366.96
A27: 24 | B27: A1304 | C27: 梁艳红 | H27: 0 | I27: 0 | J27: 500.48 | K27: 0 | L27: 0 | Q27: =D27+E27+F27+G27+H27+I27+J27+K27+L27+M27+N27+O27+P27 -> 500.48
A28: 25 | B28: A1201 | C28: 索邦卫 | G28: 149.18 | H28: 0 | I28: 217.78 | J28: 0 | K28: 0 | L28: 0 | Q28: =D28+E28+F28+G28+H28+I28+J28+K28+L28+M28+N28+O28+P28 -> 366.96
A29: 26 | B29: A1202 | C29: 韦竹珍 | G29: 149.18 | H29: 0 | I29: 217.78 | J29: 0 | K29: 0 | L29: 0 | Q29: =D29+E29+F29+G29+H29+I29+J29+K29+L29+M29+N29+O29+P29 -> 366.96
A30: 27 | B30: A1203 | C30: 冉光新 | G30: 149.18 | H30: 0 | I30: 217.78 | J30: 0 | K30: 0 | L30: 0 | Q30: =D30+E30+F30+G30+H30+I30+J30+K30+L30+M30+N30+O30+P30 -> 366.96
A31: 28 | B31: A1204 | C31: 彭鸣忠 | H31: 0 | I31: 0 | J31: 0 | K31: 0 | L31: 0 | M31: 500.48 | Q31: =D31+E31+F31+G31+H31+I31+J31+K31+L31+M31+N31+O31+P31 -> 500.48
A32: 29 | B32: A1103 | C32: 李莎莎 | G32: 149.18 | H32: 0 | I32: 217.78 | J32: 0 | K32: 0 | L32: 0 | M32: 0 | Q32: =D32+E32+F32+G32+H32+I32+J32+K32+L32+M32+N32+O32+P32 -> 366.96
A33: 30 | B33: A1104 | C33: 陈臻慧 | H33: 0 | I33: 366.96 | J33: 0 | K33: 0 | L33: 0 | M33: 0 | Q33: =D33+E33+F33+G33+H33+I33+J33+K33+L33+M33+N33+O33+P33 -> 366.96
A34: 31 | B34: A1101 | C34: 吴爱叶 | H34: 366.96 | I34: 0 | J34: 0 | K34: 0 | L34: 0 | M34: 0 | Q34: =D34+E34+F34+G34+H34+I34+J34+K34+L34+M34+N34+O34+P34 -> 366.96
A35: 32 | B35: A1102 | C35: 岑丽娟 | G35: 149.18 | H35: 217.78 | I35: 0 | J35: 0 | K35: 0 | L35: 0 | M35: 0 | Q35: =D35+E35+F35+G35+H35+I35+J35+K35+L35+M35+N35+O35+P35 -> 366.96
A36: 33 | B36: A1001 | C36: 黄敬财 | H36: 0 | I36: 0 | J36: 0 | K36: 0 | L36: 0 | M36: 0 | Q36: =D36+E36+F36+G36+H36+I36+J36+K36+L36+M36+N36+O36+P36 -> 0
A37: 34 | B37: A1002 | C37: 韦永 | E37: 133.52 | H37: 0 | I37: 366.96 | J37: 0 | K37: 0 | L37: 0 | M37: 0 | Q37: =D37+E37+F37+G37+H37+I37+J37+K37+L37+M37+N37+O37+P37 -> 500.48
A38: 35 | B38: A1003 | C38: 黄国华 | G38: 149.18 | H38: 0 | I38: 217.78 | J38: 0 | K38: 0 | L38: 0 | M38: 0 | Q38: =D38+E38+F38+G38+H38+I38+J38+K38+L38+M38+N38+O38+P38 -> 366.96
A39: 36 | B39: A1004 | C39: 樊红 | H39: 366.96 | I39: 0 | J39: 0 | K39: 0 | L39: 0 | M39: 0 | Q39: =D39+E39+F39+G39+H39+I39+J39+K39+L39+M39+N39+O39+P39 -> 366.96
A40: 37 | B40: A901 | C40: 吴荣庆 | H40: 366.96 | I40: 0 | J40: 0 | K40: 0 | L40: 0 | M40: 0 | Q40: =D40+E40+F40+G40+H40+I40+J40+K40+L40+M40+N40+O40+P40 -> 366.96
...

Sheet 2024年 
A1: 天峨县林朵林场新场部危改房AB栋2024年度电梯维护费收缴情况登记表
A2: 编制部门：天峨县林朵林场计划财务科 | O2: 单位：元
A3: 编号 | B3: 房号 | C3: 原户主 | D3: 2018年-2024年应交 | E3: 1月已交 | F3: 2月已交 | G3: 3月已交 | H3: 4月已交 | I3: 5月已交 | J3: 6月已交 | K3: 7月已交 | L3: 8月已交 | M3: 9月已交 | N3: 10月已交 | O3: 11月已交 | P3: 12月已交 | Q3: 本年已交合计 | R3: 2018年-2024年已交 | S3: 本年余额（+）或欠交（-）
A4: 1 | B4: A1801 | C4: 韦贞鸾 | D4: 2522.61 | J4: 264.02 | O4: 931.06 | P4: 0 | Q4: =SUM(E4:P4) -> 1195.08 | R4: =Q4+'2023年 '!Q4+'2022年 '!Q4+'2021年 '!Q4+'2020年 '!Q4+'2019年 '!Q4+'2018年'!Q4 -> 2889.5 | S4: =R4-D4 -> 366.89
A5: 2 | B5: A1802 | C5: 杨桂玉 | D5: 2522.61 | I5: 264.02 | O5: 931.06 | P5: 0 | Q5: =SUM(E5:P5) -> 1195.08 | R5: =Q5+'2023年 '!Q5+'2022年 '!Q5+'2021年 '!Q5+'2020年 '!Q5+'2019年 '!Q5+'2018年'!Q5 -> 3038.65 | S5: =R5-D5 -> 516.04
A6: 3 | B6: A1803 | C6: 胡远必 | D6: 2522.61 | I6: 264.02 | O6: 931.06 | P6: 0 | Q6: =SUM(E6:P6) -> 1195.08 | R6: =Q6+'2023年 '!Q6+'2022年 '!Q6+'2021年 '!Q6+'2020年 '!Q6+'2019年 '!Q6+'2018年'!Q6 -> 3038.65 | S6: =R6-D6 -> 516.04
A7: 4 | B7: A1804 | C7: 梁小凤 | D7: 2522.61 | E7: 366.96 | J7: 264.02 | O7: 931.06 | P7: 0 | Q7: =SUM(E7:P7) -> 1562.04 | R7: =Q7+'2023年 '!Q7+'2022年 '!Q7+'2021年 '!Q7+'2020年 '!Q7+'2019年 '!Q7+'2018年'!Q7 -> 3187.86 | S7: =R7-D7 -> 665.25
A8: 5 | B8: A1701 | C8: 陈巧玲 | D8: 2522.61 | I8: 264.02 | O8: 931.06 | P8: 0 | Q8: =SUM(E8:P8) -> 1195.08 | R8: =Q8+'2023年 '!Q8+'2022年 '!Q8+'2021年 '!Q8+'2020年 '!Q8+'2019年 '!Q8+'2018年'!Q8 -> 3038.68 | S8: =R8-D8 -> 516.07
A9: 6 | B9: A1702 | C9: 周凤琼 | D9: 2522.61 | K9: 264.02 | O9: 931.06 | P9: 0 | Q9: =SUM(E9:P9) -> 1195.08 | R9: =Q9+'2023年 '!Q9+'2022年 '!Q9+'2021年 '!Q9+'2020年 '!Q9+'2019年 '!Q9+'2018年'!Q9 -> 3038.65 | S9: =R9-D9 -> 516.04
A10: 7 | B10: A1703 | C10: 班华钊 | D10: 2522.61 | I10: 264.02 | O10: 931.06 | P10: 0 | Q10: =SUM(E10:P10) -> 1195.08 | R10: =Q10+'2023年 '!Q10+'2022年 '!Q10+'2021年 '!Q10+'2020年 '!Q10+'2019年 '!Q10+'2018年'!Q10 -> 3038.65 | S10: =R10-D10 -> 516.04
A11: 8 | B11: A1704 | C11: 孙慧芳 | D11: 2522.61 | J11: 264.02 | O11: 931.06 | P11: 0 | Q11: =SUM(E11:P11) -> 1195.08 | R11: =Q11+'2023年 '!Q11+'2022年 '!Q11+'2021年 '!Q11+'2020年 '!Q11+'2019年 '!Q11+'2018年'!Q11 -> 3054.31 | S11: =R11-D11 -> 531.7
A12: 9 | B12: A1601 | C12: 赵花萄 | D12: 2522.61 | I12: 264.02 | O12: 931.06 | P12: 0 | Q12: =SUM(E12:P12) -> 1195.08 | R12: =Q12+'2023年 '!Q12+'2022年 '!Q12+'2021年 '!Q12+'2020年 '!Q12+'2019年 '!Q12+'2018年'!Q12 -> 3187.83 | S12: =R12-D12 -> 665.22
A13: 10 | B13: A1602 | C13: 韦玉林 | D13: 2092.93 | O13: 931.06 | P13: 0 | Q13: =SUM(E13:P13) -> 931.06 | R13: =Q13+'2023年 '!Q13+'2022年 '!Q13+'2021年 '!Q13+'2020年 '!Q13+'2019年 '!Q13+'2018年'!Q13 -> 1645.76 | S13: =R13-D13 -> -447.17
A14: 11 | B14: A1603 | C14: 李祖勋 | D14: 1836.62 | M14: 264.02 | O14: 931.06 | P14: 0 | Q14: =SUM(E14:P14) -> 1195.08 | R14: =Q14+'2023年 '!Q14+'2022年 '!Q14+'2021年 '!Q14+'2020年 '!Q14+'2019年 '!Q14+'2018年'!Q14 -> 2301.49 | S14: =R14-D14 -> 464.87
A15: 12 | B15: A1604 | C15: 马尚军 | D15: 2522.61 | I15: 264.02 | O15: 931.06 | P15: 0 | Q15: =SUM(E15:P15) -> 1195.08 | R15: =Q15+'2023年 '!Q15+'2022年 '!Q15+'2021年 '!Q15+'2020年 '!Q15+'2019年 '!Q15+'2018年'!Q15 -> 3038.65 | S15: =R15-D15 -> 516.04
A16: 13 | B16: A1501 | C16: 杨凤英 | D16: 2522.61 | K16: 264.02 | O16: 931.06 | P16: 0 | Q16: =SUM(E16:P16) -> 1195.08 | R16: =Q16+'2023年 '!Q16+'2022年 '!Q16+'2021年 '!Q16+'2020年 '!Q16+'2019年 '!Q16+'2018年'!Q16 -> 3038.65 | S16: =R16-D16 -> 516.04
A17: 14 | B17: A1502 | C17: 陈曙林 | D17: 170 | O17: 170 | P17: 0 | Q17: =SUM(E17:P17) -> 170 | R17: =Q17+'2023年 '!Q17+'2022年 '!Q17+'2021年 '!Q17+'2020年 '!Q17+'2019年 '!Q17+'2018年'!Q17 -> 170 | S17: =R17-D17 -> 0
A18: 15 | B18: A1503 | C18: 韦月鸾 | D18: 170 | O18: 170 | P18: 0 | Q18: =SUM(E18:P18) -> 170 | R18: =Q18+'2023年 '!Q18+'2022年 '!Q18+'2021年 '!Q18+'2020年 '!Q18+'2019年 '!Q18+'2018年'!Q18 -> 170 | S18: =R18-D18 -> 0
A19: 16 | B19: A1504 | C19: 方焕忠 | D19: 2522.61 | I19: 264.02 | O19: 931.06 | P19: 0 | Q19: =SUM(E19:P19) -> 1195.08 | R19: =Q19+'2023年 '!Q19+'2022年 '!Q19+'2021年 '!Q19+'2020年 '!Q19+'2019年 '!Q19+'2018年'!Q19 -> 3038.65 | S19: =R19-D19 -> 516.04
A20: 17 | B20: A1401 | C20: 李向农 | D20: 2522.61 | O20: 931.06 | P20: 0 | Q20: =SUM(E20:P20) -> 931.06 | R20: =Q20+'2023年 '!Q20+'2022年 '!Q20+'2021年 '!Q20+'2020年 '!Q20+'2019年 '!Q20+'2018年'!Q20 -> 2923.81 | S20: =R20-D20 -> 401.2
A21: 18 | B21: A1402 | C21: 邓扬静 | D21: 2522.61 | I21: 264.02 | O21: 931.06 | P21: 0 | Q21: =SUM(E21:P21) -> 1195.08 | R21: =Q21+'2023年 '!Q21+'2022年 '!Q21+'2021年 '!Q21+'2020年 '!Q21+'2019年 '!Q21+'2018年'!Q21 -> 2928.73 | S21: =R21-D21 -> 406.12
A22: 19 | B22: A1403 | C22: 黄光龙 | D22: 2522.61 | I22: 264.02 | O22: 931.06 | P22: 0 | Q22: =SUM(E22:P22) -> 1195.08 | R22: =Q22+'2023年 '!Q22+'2022年 '!Q22+'2021年 '!Q22+'2020年 '!Q22+'2019年 '!Q22+'2018年'!Q22 -> 3297.78 | S22: =R22-D22 -> 775.17
A23: 20 | B23: A1404 | C23: 杨光权 | D23: 2522.61 | I23: 264.02 | O23: 931.06 | P23: 0 | Q23: =SUM(E23:P23) -> 1195.08 | R23: =Q23+'2023年 '!Q23+'2022年 '!Q23+'2021年 '!Q23+'2020年 '!Q23+'2019年 '!Q23+'2018年'!Q23 -> 3038.68 | S23: =R23-D23 -> 516.07
A24: 21 | B24: A1301 | C24: 吴胜斌 | D24: 2390.67 | N24: 104.02 | O24: 112 | P24: 320 | Q24: =SUM(E24:P24) -> 536.02 | R24: =Q24+'2023年 '!Q24+'2022年 '!Q24+'2021年 '!Q24+'2020年 '!Q24+'2019年 '!Q24+'2018年'!Q24 -> 2379.59 | S24: =R24-D24 -> -11.08
A25: 22 | B25: A1302 | C25: 韦献萍 | D25: 2522.61 | J25: 264.02 | O25: 931.06 | P25: 0 | Q25: =SUM(E25:P25) -> 1195.08 | R25: =Q25+'2023年 '!Q25+'2022年 '!Q25+'2021年 '!Q25+'2020年 '!Q25+'2019年 '!Q25+'2018年'!Q25 -> 3172.17 | S25: =R25-D25 -> 649.56
A26: 23 | B26: A1303 | C26: 黄汉冕 | D26: 2522.61 | I26: 264.02 | O26: 931.06 | P26: 0 | Q26: =SUM(E26:P26) -> 1195.08 | R26: =Q26+'2023年 '!Q26+'2022年 '!Q26+'2021年 '!Q26+'2020年 '!Q26+'2019年 '!Q26+'2018年'!Q26 -> 3038.65 | S26: =R26-D26 -> 516.04
A27: 24 | B27: A1304 | C27: 梁艳红 | D27: 2522.61 | K27: 264.02 | O27: 931.06 | P27: 0 | Q27: =SUM(E27:P27) -> 1195.08 | R27: =Q27+'2023年 '!Q27+'2022年 '!Q27+'2021年 '!Q27+'2020年 '!Q27+'2019年 '!Q27+'2018年'!Q27 -> 3038.73 | S27: =R27-D27 -> 516.12
A28: 25 | B28: A1201 | C28: 索邦卫 | D28: 2522.61 | I28: 264.02 | O28: 931.06 | P28: 0 | Q28: =SUM(E28:P28) -> 1195.08 | R28: =Q28+'2023年 '!Q28+'2022年 '!Q28+'2021年 '!Q28+'2020年 '!Q28+'2019年 '!Q28+'2018年'!Q28 -> 3038.65 | S28: =R28-D28 -> 516.04
A29: 26 | B29: A1202 | C29: 韦竹珍 | D29: 2522.61 | I29: 264.02 | O29: 385.93 | P29: 545.13 | Q29: =SUM(E29:P29) -> 1195.08 | R29: =Q29+'2023年 '!Q29+'2022年 '!Q29+'2021年 '!Q29+'2020年 '!Q29+'2019年 '!Q29+'2018年'!Q29 -> 3038.65 | S29: =R29-D29 -> 516.04
A30: 27 | B30: A1203 | C30: 冉光新 | D30: 2522.61 | I30: 264.02 | O30: 931.06 | P30: 0 | Q30: =SUM(E30:P30) -> 1195.08 | R30: =Q30+'2023年 '!Q30+'2022年 '!Q30+'2021年 '!Q30+'2020年 '!Q30+'2019年 '!Q30+'2018年'!Q30 -> 2718.39 | S30: =R30-D30 -> 195.78
A31: 28 | B31: A1204 | C31: 彭鸣忠 | D31: 2324.68 | N31: 264.02 | O31: 931.06 | P31: 0 | Q31: =SUM(E31:P31) -> 1195.08 | R31: =Q31+'2023年 '!Q31+'2022年 '!Q31+'2021年 '!Q31+'2020年 '!Q31+'2019年 '!Q31+'2018年'!Q31 -> 3038.65 | S31: =R31-D31 -> 713.97
A32: 29 | B32: A1101 | C32: 李莎莎 | D32: 2522.61 | K32: 264.02 | O32: 931.06 | P32: 0 | Q32: =SUM(E32:P32) -> 1195.08 | R32: =Q32+'2023年 '!Q32+'2022年 '!Q32+'2021年 '!Q32+'2020年 '!Q32+'2019年 '!Q32+'2018年'!Q32 -> 3038.65 | S32: =R32-D32 -> 516.04
A33: 30 | B33: A1102 | C33: 陈臻慧 | D33: 2522.61 | I33: 264.02 | O33: 931.06 | P33: 0 | Q33: =SUM(E33:P33) -> 1195.08 | R33: =Q33+'2023年 '!Q33+'2022年 '!Q33+'2021年 '!Q33+'2020年 '!Q33+'2019年 '!Q33+'2018年'!Q33 -> 3038.68 | S33: =R33-D33 -> 516.07
A34: 31 | B34: A1103 | C34: 吴爱叶 | D34: 2522.61 | O34: 931.06 | P34: 0 | Q34: =SUM(E34:P34) -> 931.06 | R34: =Q34+'2023年 '!Q34+'2022年 '!Q34+'2021年 '!Q34+'2020年 '!Q34+'2019年 '!Q34+'2018年'!Q34 -> 2751.11 | S34: =R34-D34 -> 228.5
A35: 32 | B35: A1104 | C35: 岑丽娟 | D35: 2202.85 | K35: 264.02 | O35: 0 | P35: 0 | Q35: =SUM(E35:P35) -> 264.02 | R35: =Q35+'2023年 '!Q35+'2022年 '!Q35+'2021年 '!Q35+'2020年 '!Q35+'2019年 '!Q35+'2018年'!Q35 -> 1389.09 | S35: =R35-D35 -> -813.76
A36: 33 | B36: A1001 | C36: 黄敬财 | D36: 170 | O36: 170 | P36: 0 | Q36: =SUM(E36:P36) -> 170 | R36: =Q36+'2023年 '!Q36+'2022年 '!Q36+'2021年 '!Q36+'2020年 '!Q36+'2019年 '!Q36+'2018年'!Q36 -> 170 | S36: =R36-D36 -> 0
A37: 34 | B37: A1002 | C37: 韦永 | D37: 2522.61 | I37: 264.02 | O37: 931.06 | P37: 0 | Q37: =SUM(E37:P37) -> 1195.08 | R37: =Q37+'2023年 '!Q37+'2022年 '!Q37+'2021年 '!Q37+'2020年 '!Q37+'2019年 '!Q37+'2018年'!Q37 -> 3038.65 | S37: =R37-D37 -> 516.04
A38: 35 | B38: A1003 | C38: 黄国华 | D38: 2522.61 | L38: 264.02 | O38: 931.06 | P38: 0 | Q38: =SUM(E38:P38) -> 1195.08 | R38: =Q38+'2023年 '!Q38+'2022年 '!Q38+'2021年 '!Q38+'2020年 '!Q38+'2019年 '!Q38+'2018年'!Q38 -> 3038.65 | S38: =R38-D38 -> 516.04
A39: 36 | B39: A1004 | C39: 樊红 | D39: 2522.61 | O39: 931.06 | P39: 0 | Q39: =SUM(E39:P39) -> 931.06 | R39: =Q39+'2023年 '!Q39+'2022年 '!Q39+'2021年 '!Q39+'2020年 '!Q39+'2019年 '!Q39+'2018年'!Q39 -> 2774.63 | S39: =R39-D39 -> 252.02
A40: 37 | B40: A901 | C40: 吴荣庆 | D40: 2522.61 | J40: 200 | O40: 931.06 | P40: 0 | Q40: =SUM(E40:P40) -> 1131.06 | R40: =Q40+'2023年 '!Q40+'2022年 '!Q40+'2021年 '!Q40+'2020年 '!Q40+'2019年 '!Q40+'2018年'!Q40 -> 3084.55 | S40: =R40-D40 -> 561.94
...

Sheet 2025年 
A1: 天峨县林朵林场新场部危改房AB栋2025年度电梯维护费收缴情况登记表
A2: 编制部门：天峨县林朵林场计划财务科 | O2: 单位：元
A3: 编号 | B3: 房号 | C3: 原户主 | D3: 上年余额（+）或欠交（-） | E3: 1月已交 | F3: 2月已交 | G3: 3月已交 | H3: 4月已交 | I3: 5月已交 | J3: 6月已交 | K3: 7月已交 | L3: 8月已交 | M3: 9月已交 | N3: 10月已交 | O3: 11月已交 | P3: 12月已交 | Q3: 本年余额（+）或欠交（-）
A4: 1 | B4: A1801 | C4: 韦贞鸾 | D4: 366.89 | Q4: =D4+E4+F4+G4+H4+I4+J4+K4+L4+M4+N4+O4+P4 -> 366.89
A5: 2 | B5: A1802 | C5: 杨桂玉 | D5: 516.04 | Q5: =D5+E5+F5+G5+H5+I5+J5+K5+L5+M5+N5+O5+P5 -> 516.04
A6: 3 | B6: A1803 | C6: 胡远必 | D6: 516.04 | Q6: =D6+E6+F6+G6+H6+I6+J6+K6+L6+M6+N6+O6+P6 -> 516.04
A7: 4 | B7: A1804 | C7: 梁小凤 | D7: 665.25 | Q7: =D7+E7+F7+G7+H7+I7+J7+K7+L7+M7+N7+O7+P7 -> 665.25
A8: 5 | B8: A1701 | C8: 陈巧玲 | D8: 516.07 | Q8: =D8+E8+F8+G8+H8+I8+J8+K8+L8+M8+N8+O8+P8 -> 516.07
A9: 6 | B9: A1702 | C9: 周凤琼 | D9: 516.04 | Q9: =D9+E9+F9+G9+H9+I9+J9+K9+L9+M9+N9+O9+P9 -> 516.04
A10: 7 | B10: A1703 | C10: 班华钊 | D10: 516.04 | Q10: =D10+E10+F10+G10+H10+I10+J10+K10+L10+M10+N10+O10+P10 -> 516.04
A11: 8 | B11: A1704 | C11: 孙慧芳 | D11: 531.7 | Q11: =D11+E11+F11+G11+H11+I11+J11+K11+L11+M11+N11+O11+P11 -> 531.7
A12: 9 | B12: A1601 | C12: 赵花萄 | D12: 665.22 | Q12: =D12+E12+F12+G12+H12+I12+J12+K12+L12+M12+N12+O12+P12 -> 665.22
A13: 10 | B13: A1602 | C13: 韦玉林 | D13: -447.17 | Q13: =D13+E13+F13+G13+H13+I13+J13+K13+L13+M13+N13+O13+P13 -> -447.17
A14: 11 | B14: A1603 | C14: 李祖勋 | D14: 464.87 | Q14: =D14+E14+F14+G14+H14+I14+J14+K14+L14+M14+N14+O14+P14 -> 464.87
A15: 12 | B15: A1604 | C15: 马尚军 | D15: 516.04 | Q15: =D15+E15+F15+G15+H15+I15+J15+K15+L15+M15+N15+O15+P15 -> 516.04
... A127: 124 | B127: B404 | C127: 周冬梅 | D127: 731.33 | Q127: =D127+E127+F127+G127+H127+I127+J127+K127+L127+M127+N127+O127+P127 -> 731.33
A128: 125 | B128: B301 | D128: 0 | Q128: =D128+E128+F128+G128+H128+I128+J128+K128+L128+M128+N128+O128+P128 -> 0
A129: 126 | B129: B302 | C129: 田明川 | D129: 665.19 | Q129: =D129+E129+F129+G129+H129+I129+J129+K129+L129+M129+N129+O129+P129 -> 665.19
A130: 127 | B130: B303 | C130: 韦仕斌 | D130: 731.33 | Q130: =D130+E130+F130+G130+H130+I130+J130+K130+L130+M130+N130+O130+P130 -> 731.33
A131: 128 | B131: B304 | C131: 韦光伟 | D131: 81.17 | Q131: =D131+E131+F131+G131+H131+I131+J131+K131+L131+M131+N131+O131+P131 -> 81.17
A132: 129 | C132: 合计 | D132: =SUM(D4:D131) -> 72780.56 | E132: =SUM(E4:E131) -> 0 | F132: =SUM(F4:F131) -> 0 | G132: =SUM(G4:G131) -> 0 | H132: =SUM(H4:H131) -> 0 | I132: =SUM(I4:I131) -> 0 | J132: =SUM(J4:J131) -> 0 | K132: =SUM(K4:K131) -> 0 | ... Q132: =SUM(Q4:Q131) -> 72780.56
